<?xml version="1.0" ?>

<robot name="my_robot">

  <material name="orange">
    <color rgba="1 0.35 0 1"/>
  </material>

  <material name="gray">
    <color rgba="0.5 0.5 0.5 1"/>
  </material>

  <material name="black">
    <color rgba="0 0 0 1"/>
  </material>


  <!-- Robot Properties -->

    
  <!-- Base Footprint -->
  <link name="base_footprint"/>

  <!-- Base Link -->
  <link name="base_link">
    <visual>
      <geometry>
        <box size="0.5 0.35 0.1"/>
      </geometry>
      <material name="orange"/>
      <origin rpy="0 0 0" xyz="0 0 0.05"/>
    </visual>
    <collision>
      <geometry>
        <box size="0.5 0.35 0.1"/>
      </geometry>
      <material name="orange"/>
      <origin rpy="0 0 0" xyz="0 0 0.05"/>
    </collision>
    <inertial>
      <origin rpy="0 0 0" xyz="0 0 0.05"/>
      <mass value="5.0"/>
      <inertia ixx="0.10833333333333334" ixy="0" ixz="0" iyy="0.15520833333333334" iyz="0" izz="0.055208333333333325"/>
    </inertial>
  </link>


  <link name="right_r_wheel_link">
    <visual>
      <geometry>
        <cylinder length="0.03" radius="0.08"/>
      </geometry>
      <origin rpy="1.5707963267948966 0 0" xyz="0 0 0"/>   \\ rotat wheel 180 degree about X axis  
      <material name="gray"/>
    </visual>
    <collision>
      <geometry>
        <cylinder length="0.03" radius="0.08"/>
      </geometry>
      <origin rpy="1.5707963267948966 0 0" xyz="0 0 0"/> rotat wheel 180 degree about X axis
    </collision>
    <inertial>
      <origin rpy="1.5707963267948966 0 0" xyz="0 0 0"/>
      <mass value="0.5"/>
      <inertia ixx="0.0008374999999999999" ixy="0" ixz="0" iyy="0.0008374999999999999" iyz="0" izz="0.0016"/>
    </inertial>
  </link>


  <link name="right_f_wheel_link">
    <visual>
      <geometry>
        <cylinder length="0.03" radius="0.08"/>
      </geometry>
      <origin rpy="1.5707963267948966 0 0" xyz="0 0 0"/>  rotat wheel 180 degree about X axis
      <material name="gray"/>
    </visual>
    <collision>
      <geometry>
        <cylinder length="0.03" radius="0.08"/>
      </geometry>
      <origin rpy="1.5707963267948966 0 0" xyz="0 0 0"/> rotat wheel 180 degree about X axis
    </collision>
    <inertial>
      <origin rpy="1.5707963267948966 0 0" xyz="0 0 0"/>
      <mass value="0.5"/>
      <inertia ixx="0.0008374999999999999" ixy="0" ixz="0" iyy="0.0008374999999999999" iyz="0" izz="0.0016"/>
    </inertial>
  </link>


  <link name="left_r_wheel_link">
    <visual>
      <geometry>
        <cylinder length="0.03" radius="0.08"/>
      </geometry>
      <origin rpy="1.5707963267948966 0 0" xyz="0 0 0"/>  rotat wheel 180 degree about X axis
      <material name="gray"/>
    </visual>
    <collision>
      <geometry>
        <cylinder length="0.03" radius="0.08"/>
      </geometry>
      <origin rpy="1.5707963267948966 0 0" xyz="0 0 0"/>  rotat wheel 180 degree about X axis
    </collision>
    <inertial>
      <origin rpy="1.5707963267948966 0 0" xyz="0 0 0"/>
      <mass value="0.5"/>
      <inertia ixx="0.0008374999999999999" ixy="0" ixz="0" iyy="0.0008374999999999999" iyz="0" izz="0.0016"/>
    </inertial>
  </link>


  <link name="left_f_wheel_link">
    <visual>
      <geometry>
        <cylinder length="0.03" radius="0.08"/>
      </geometry>
      <origin rpy="1.5707963267948966 0 0" xyz="0 0 0"/> rotat wheel 180 degree about X axis  
      <material name="gray"/>
    </visual>
    <collision>
      <geometry>
        <cylinder length="0.03" radius="0.08"/>
      </geometry>
      <origin rpy="1.5707963267948966 0 0" xyz="0 0 0"/>  rotat wheel 180 degree about X axis       
    </collision>
    <inertial>
      <origin rpy="1.5707963267948966 0 0" xyz="0 0 0"/>
      <mass value="0.5"/>
      <inertia ixx="0.0008374999999999999" ixy="0" ixz="0" iyy="0.0008374999999999999" iyz="0" izz="0.0016"/>
    </inertial>
  </link>


  <!-- Fixed Joint for Base -->
  <joint name="base_joint" type="fixed">
    <parent link="base_footprint"/>
    <child link="base_link"/>
    <origin rpy="0 0 0" xyz="0 0 0.05"/>    
  </joint>


  <!-- Continuous Joints for Wheels -->
  <!-- Rear Right Wheel -->
  <joint name="base_right_wheel_r_joint" type="continuous">
    <parent link="base_link"/>
    <child link="right_r_wheel_link"/>
    <origin rpy="0 0 0" xyz="-0.18 -0.19 0.03"/>        
    <axis xyz="0 1 0"/>
  </joint>


  <!-- Front Right Wheel -->
  <joint name="base_right_wheel_f_joint" type="continuous">
    <parent link="base_link"/>
    <child link="right_f_wheel_link"/>
    <origin rpy="0 0 0" xyz="0.18 -0.19 0.03"/>
    <axis xyz="0 1 0"/>
  </joint>


  <!-- Rear Left Wheel -->
  <joint name="base_left_wheel_r_joint" type="continuous">
    <parent link="base_link"/>
    <child link="left_r_wheel_link"/>
    <origin rpy="0 0 0" xyz="-0.18 0.19 0.03"/>
    <axis xyz="0 1 0"/>
  </joint>


  <!-- Front Left Wheel -->
  <joint name="base_left_wheel_f_joint" type="continuous">
    <parent link="base_link"/>
    <child link="left_f_wheel_link"/>
    <origin rpy="0 0 0" xyz="0.18 0.19 0.03"/>
    <axis xyz="0 1 0"/>
  </joint>



  <gazebo reference="base_link">
    <material>Gazebo/Orange</material>
  </gazebo>
  <gazebo reference="right_r_wheel_link">
    <material>Gazebo/Gray</material>
  </gazebo>
  <gazebo reference="right_f_wheel_link">
    <material>Gazebo/Gray</material>
  </gazebo>
  <gazebo reference="left_f_wheel_link">
    <material>Gazebo/Gray</material>
  </gazebo>
  <gazebo reference="left_r_wheel_link">
    <material>Gazebo/Gray</material>
  </gazebo>


  
  <gazebo>
    <plugin filename="libgazebo_ros_diff_drive.so" name="front_wheel">
      <!-- Wheel Information -->
      <left_joint>base_left_wheel_f_joint</left_joint>
      <right_joint>base_right_wheel_f_joint</right_joint>
      <wheel_separation>0.064</wheel_separation>
      <wheel_diameter>1.6</wheel_diameter>
      <!-- Limit -->
      <max_wheel_torque>200</max_wheel_torque>
      <max_wheel_acceleration>10.0</max_wheel_acceleration>
      <!-- Output -->
      <odometry_frame>odom</odometry_frame>
      <robot_base_frame>base_footprint</robot_base_frame>
      <publish_odom>true</publish_odom>
      <publish_odom_tf>true</publish_odom_tf>
      <publish_wheel_tf>true</publish_wheel_tf>
    </plugin>
  </gazebo>


  <gazebo>
    <plugin filename="libgazebo_ros_diff_drive.so" name="rear_wheel">
      <!-- Wheel Information -->
      <left_joint>base_left_wheel_r_joint</left_joint>
      <right_joint>base_right_wheel_r_joint</right_joint>
      <wheel_separation>0.064</wheel_separation>
      <wheel_diameter>1.6</wheel_diameter>
      <!-- Limit -->
      <max_wheel_torque>200</max_wheel_torque>
      <max_wheel_acceleration>10.0</max_wheel_acceleration>
      <!-- Output -->
      <odometry_frame>odom</odometry_frame>
      <robot_base_frame>base_footprint</robot_base_frame>
      <publish_odom>true</publish_odom>
      <publish_odom_tf>true</publish_odom_tf>
      <publish_wheel_tf>true</publish_wheel_tf>
    </plugin>
  </gazebo>


  <!-- LiDAR Link -->
  <link name="laser_frame">
    <visual>
      <geometry>
        <cylinder length="0.02" radius="0.05"/>
      </geometry>
      <material name="black"/>
    </visual>
    <collision>
      <geometry>
        <cylinder length="0.02" radius="0.05"/>
      </geometry>
    </collision>
    <inertial>
      <origin rpy="0 0 0" xyz="0 0 0"/>
      <mass value="0.2"/>
      <inertia ixx="0.00013166666666666668" ixy="0" ixz="0" iyy="0.00013166666666666668" iyz="0" izz="0.00025000000000000006"/>
    </inertial>
  </link>


  <!-- LiDAR Joint -->
  <joint name="base_lidar_joint" type="fixed">
    <parent link="base_link"/>
    <child link="laser_frame"/>
    <origin rpy="0 0 0" xyz="0.2 0 0.12"/>
  </joint>



  <!-- Gazebo Plugin for LiDAR -->
  <gazebo reference="laser_frame">
    <material>Gazebo/Black</material>
    <sensor name="lidar_sensor" type="ray">
      <pose>0 0 0 0 0 0</pose>
      <visualize>true</visualize>
      <update_rate>10</update_rate>
      <ray>
        <scan>
          <horizontal>
            <samples>360</samples>
            <min_angle>-3.14</min_angle>
            <max_angle>3.14</max_angle>
          </horizontal>
        </scan>
        <range>
          <min>0.1</min>
          <max>10</max>
        </range>
      </ray>
      <plugin filename="libgazebo_ros_ray_sensor.so" name="laser_controller">
        <ros>
          <argument>~/out:=scan</argument>
        </ros>
        <output_type>sensor_msgs/LaserScan</output_type>
        <frame_name>laser_frame</frame_name>
      </plugin>
    </sensor>
  </gazebo>


</robot>